[32m2023-12-18 14:10:40 +0000[0m - dagster - [34mDEBUG[0m - __ASSET_JOB - 1f727e7c-7a94-40a5-997d-9f536e90810b - 6806 - LOGS_CAPTURED - Started capturing logs in process (pid: 6806).
[32m2023-12-18 14:10:40 +0000[0m - dagster - [34mDEBUG[0m - __ASSET_JOB - 1f727e7c-7a94-40a5-997d-9f536e90810b - 6806 - PercentageFullTimeAndPartTimePerDepartment - STEP_START - Started execution of step "PercentageFullTimeAndPartTimePerDepartment".
[32m2023-12-18 14:10:40 +0000[0m - dagster - [34mERROR[0m - [31m__ASSET_JOB - 1f727e7c-7a94-40a5-997d-9f536e90810b - 6806 - PercentageFullTimeAndPartTimePerDepartment - STEP_FAILURE - Execution of step "PercentageFullTimeAndPartTimePerDepartment" failed.

dagster._core.errors.DagsterExecutionStepExecutionError: Error occurred while executing op "PercentageFullTimeAndPartTimePerDepartment"::

KeyError: 'full or part-time'

Stack Trace:
  File "/Users/nirmalgeorge/anaconda3/lib/python3.11/site-packages/dagster/_core/execution/plan/utils.py", line 54, in op_execution_error_boundary
    yield
  File "/Users/nirmalgeorge/anaconda3/lib/python3.11/site-packages/dagster/_utils/__init__.py", line 465, in iterate_with_context
    next_output = next(iterator)
                  ^^^^^^^^^^^^^^
  File "/Users/nirmalgeorge/anaconda3/lib/python3.11/site-packages/dagster/_core/execution/plan/compute_generator.py", line 131, in _coerce_op_compute_fn_to_iterator
    result = invoke_compute_fn(
             ^^^^^^^^^^^^^^^^^^
  File "/Users/nirmalgeorge/anaconda3/lib/python3.11/site-packages/dagster/_core/execution/plan/compute_generator.py", line 125, in invoke_compute_fn
    return fn(context, **args_to_pass) if context_arg_provided else fn(**args_to_pass)
                                                                    ^^^^^^^^^^^^^^^^^^
  File "/Users/nirmalgeorge/dap_dagster_project/DAP-project/govt_employee_analysis/govt_employee_analysis/assets.py", line 110, in PercentageFullTimeAndPartTimePerDepartment
    contingency_table = pd.crosstab(df['department'], df['full or part-time'], margins=True, margins_name="Total")
                                                      ~~^^^^^^^^^^^^^^^^^^^^^
  File "/Users/nirmalgeorge/anaconda3/lib/python3.11/site-packages/pandas/core/frame.py", line 3807, in __getitem__
    indexer = self.columns.get_loc(key)
              ^^^^^^^^^^^^^^^^^^^^^^^^^
  File "/Users/nirmalgeorge/anaconda3/lib/python3.11/site-packages/pandas/core/indexes/base.py", line 3804, in get_loc
    raise KeyError(key) from err

The above exception was caused by the following exception:
KeyError: 'full or part-time'

Stack Trace:
  File "/Users/nirmalgeorge/anaconda3/lib/python3.11/site-packages/pandas/core/indexes/base.py", line 3802, in get_loc
    return self._engine.get_loc(casted_key)
           ^^^^^^^^^^^^^^^^^^^^^^^^^^^^^^^^
  File "pandas/_libs/index.pyx", line 138, in pandas._libs.index.IndexEngine.get_loc
  File "pandas/_libs/index.pyx", line 165, in pandas._libs.index.IndexEngine.get_loc
  File "pandas/_libs/hashtable_class_helper.pxi", line 5745, in pandas._libs.hashtable.PyObjectHashTable.get_item
  File "pandas/_libs/hashtable_class_helper.pxi", line 5753, in pandas._libs.hashtable.PyObjectHashTable.get_item
[0m
