[32m2023-12-18 19:21:32 +0000[0m - dagster - [34mDEBUG[0m - __ASSET_JOB - 1e8be710-537b-41ca-a339-8f7fb002e617 - 17804 - LOGS_CAPTURED - Started capturing logs in process (pid: 17804).
[32m2023-12-18 19:21:32 +0000[0m - dagster - [34mDEBUG[0m - __ASSET_JOB - 1e8be710-537b-41ca-a339-8f7fb002e617 - 17804 - voucher_dist_Jan2022ToDec2023 - STEP_START - Started execution of step "voucher_dist_Jan2022ToDec2023".
[32m2023-12-18 19:21:32 +0000[0m - dagster - [34mDEBUG[0m - __ASSET_JOB - 1e8be710-537b-41ca-a339-8f7fb002e617 - voucher_dist_Jan2022ToDec2023 - Loading file from: /Users/nirmalgeorge/dap_dagster_project/DAP-project/govt_employee_analysis/tmpjy9nrer1/storage/Merged_data using PickledObjectFilesystemIOManager...
[32m2023-12-18 19:21:32 +0000[0m - dagster - [34mDEBUG[0m - __ASSET_JOB - 1e8be710-537b-41ca-a339-8f7fb002e617 - 17804 - voucher_dist_Jan2022ToDec2023 - ASSET_OBSERVATION - DagsterEventType.ASSET_OBSERVATION for step voucher_dist_Jan2022ToDec2023
[32m2023-12-18 19:21:32 +0000[0m - dagster - [34mDEBUG[0m - __ASSET_JOB - 1e8be710-537b-41ca-a339-8f7fb002e617 - 17804 - voucher_dist_Jan2022ToDec2023 - LOADED_INPUT - Loaded input "Merged_data" using input manager "io_manager"
[32m2023-12-18 19:21:32 +0000[0m - dagster - [34mDEBUG[0m - __ASSET_JOB - 1e8be710-537b-41ca-a339-8f7fb002e617 - 17804 - voucher_dist_Jan2022ToDec2023 - STEP_INPUT - Got input "Merged_data" of type "Any". (Type check passed).
[32m2023-12-18 19:21:32 +0000[0m - dagster - [34mERROR[0m - [31m__ASSET_JOB - 1e8be710-537b-41ca-a339-8f7fb002e617 - 17804 - voucher_dist_Jan2022ToDec2023 - STEP_FAILURE - Execution of step "voucher_dist_Jan2022ToDec2023" failed.

dagster._core.errors.DagsterExecutionStepExecutionError: Error occurred while executing op "voucher_dist_Jan2022ToDec2023"::

KeyError: 'date'

Stack Trace:
  File "/Users/nirmalgeorge/anaconda3/lib/python3.11/site-packages/dagster/_core/execution/plan/utils.py", line 54, in op_execution_error_boundary
    yield
  File "/Users/nirmalgeorge/anaconda3/lib/python3.11/site-packages/dagster/_utils/__init__.py", line 465, in iterate_with_context
    next_output = next(iterator)
                  ^^^^^^^^^^^^^^
  File "/Users/nirmalgeorge/anaconda3/lib/python3.11/site-packages/dagster/_core/execution/plan/compute_generator.py", line 131, in _coerce_op_compute_fn_to_iterator
    result = invoke_compute_fn(
             ^^^^^^^^^^^^^^^^^^
  File "/Users/nirmalgeorge/anaconda3/lib/python3.11/site-packages/dagster/_core/execution/plan/compute_generator.py", line 125, in invoke_compute_fn
    return fn(context, **args_to_pass) if context_arg_provided else fn(**args_to_pass)
           ^^^^^^^^^^^^^^^^^^^^^^^^^^^
  File "/Users/nirmalgeorge/dap_dagster_project/DAP-project/govt_employee_analysis/govt_employee_analysis/assets.py", line 204, in voucher_dist_Jan2022ToDec2023
    data_df['month'] = data_df['date'].dt.to_period('M')
                       ~~~~~~~^^^^^^^^
  File "/Users/nirmalgeorge/anaconda3/lib/python3.11/site-packages/pandas/core/frame.py", line 3807, in __getitem__
    indexer = self.columns.get_loc(key)
              ^^^^^^^^^^^^^^^^^^^^^^^^^
  File "/Users/nirmalgeorge/anaconda3/lib/python3.11/site-packages/pandas/core/indexes/base.py", line 3804, in get_loc
    raise KeyError(key) from err

The above exception was caused by the following exception:
KeyError: 'date'

Stack Trace:
  File "/Users/nirmalgeorge/anaconda3/lib/python3.11/site-packages/pandas/core/indexes/base.py", line 3802, in get_loc
    return self._engine.get_loc(casted_key)
           ^^^^^^^^^^^^^^^^^^^^^^^^^^^^^^^^
  File "pandas/_libs/index.pyx", line 138, in pandas._libs.index.IndexEngine.get_loc
  File "pandas/_libs/index.pyx", line 165, in pandas._libs.index.IndexEngine.get_loc
  File "pandas/_libs/hashtable_class_helper.pxi", line 5745, in pandas._libs.hashtable.PyObjectHashTable.get_item
  File "pandas/_libs/hashtable_class_helper.pxi", line 5753, in pandas._libs.hashtable.PyObjectHashTable.get_item
[0m
