[32m2023-12-18 19:39:27 +0000[0m - dagster - [34mDEBUG[0m - __ASSET_JOB - 2ee83baa-58c9-4a1a-a446-59b1bc5a8dc1 - 18618 - LOGS_CAPTURED - Started capturing logs in process (pid: 18618).
[32m2023-12-18 19:39:27 +0000[0m - dagster - [34mDEBUG[0m - __ASSET_JOB - 2ee83baa-58c9-4a1a-a446-59b1bc5a8dc1 - 18618 - voucher_dist_Jan2022ToDec2023 - STEP_START - Started execution of step "voucher_dist_Jan2022ToDec2023".
[32m2023-12-18 19:39:27 +0000[0m - dagster - [34mDEBUG[0m - __ASSET_JOB - 2ee83baa-58c9-4a1a-a446-59b1bc5a8dc1 - voucher_dist_Jan2022ToDec2023 - Loading file from: /Users/nirmalgeorge/dap_dagster_project/DAP-project/govt_employee_analysis/tmpjy9nrer1/storage/Merged_data using PickledObjectFilesystemIOManager...
[32m2023-12-18 19:39:27 +0000[0m - dagster - [34mDEBUG[0m - __ASSET_JOB - 2ee83baa-58c9-4a1a-a446-59b1bc5a8dc1 - 18618 - voucher_dist_Jan2022ToDec2023 - ASSET_OBSERVATION - DagsterEventType.ASSET_OBSERVATION for step voucher_dist_Jan2022ToDec2023
[32m2023-12-18 19:39:27 +0000[0m - dagster - [34mDEBUG[0m - __ASSET_JOB - 2ee83baa-58c9-4a1a-a446-59b1bc5a8dc1 - 18618 - voucher_dist_Jan2022ToDec2023 - LOADED_INPUT - Loaded input "Merged_data" using input manager "io_manager"
[32m2023-12-18 19:39:27 +0000[0m - dagster - [34mDEBUG[0m - __ASSET_JOB - 2ee83baa-58c9-4a1a-a446-59b1bc5a8dc1 - 18618 - voucher_dist_Jan2022ToDec2023 - STEP_INPUT - Got input "Merged_data" of type "Any". (Type check passed).
[32m2023-12-18 19:39:27 +0000[0m - dagster - [34mERROR[0m - [31m__ASSET_JOB - 2ee83baa-58c9-4a1a-a446-59b1bc5a8dc1 - 18618 - voucher_dist_Jan2022ToDec2023 - STEP_FAILURE - Execution of step "voucher_dist_Jan2022ToDec2023" failed.

dagster._core.errors.DagsterExecutionStepExecutionError: Error occurred while executing op "voucher_dist_Jan2022ToDec2023"::

ValueError: No axis named 1 for object type Series

Stack Trace:
  File "/Users/nirmalgeorge/anaconda3/lib/python3.11/site-packages/dagster/_core/execution/plan/utils.py", line 54, in op_execution_error_boundary
    yield
  File "/Users/nirmalgeorge/anaconda3/lib/python3.11/site-packages/dagster/_utils/__init__.py", line 465, in iterate_with_context
    next_output = next(iterator)
                  ^^^^^^^^^^^^^^
  File "/Users/nirmalgeorge/anaconda3/lib/python3.11/site-packages/dagster/_core/execution/plan/compute_generator.py", line 131, in _coerce_op_compute_fn_to_iterator
    result = invoke_compute_fn(
             ^^^^^^^^^^^^^^^^^^
  File "/Users/nirmalgeorge/anaconda3/lib/python3.11/site-packages/dagster/_core/execution/plan/compute_generator.py", line 125, in invoke_compute_fn
    return fn(context, **args_to_pass) if context_arg_provided else fn(**args_to_pass)
           ^^^^^^^^^^^^^^^^^^^^^^^^^^^
  File "/Users/nirmalgeorge/dap_dagster_project/DAP-project/govt_employee_analysis/govt_employee_analysis/assets.py", line 207, in voucher_dist_Jan2022ToDec2023
    voucher_month = voucher_month.drop('description', axis = 1)
                    ^^^^^^^^^^^^^^^^^^^^^^^^^^^^^^^^^^^^^^^^^^^
  File "/Users/nirmalgeorge/anaconda3/lib/python3.11/site-packages/pandas/util/_decorators.py", line 331, in wrapper
    return func(*args, **kwargs)
           ^^^^^^^^^^^^^^^^^^^^^
  File "/Users/nirmalgeorge/anaconda3/lib/python3.11/site-packages/pandas/core/series.py", line 5237, in drop
    return super().drop(
           ^^^^^^^^^^^^^
  File "/Users/nirmalgeorge/anaconda3/lib/python3.11/site-packages/pandas/util/_decorators.py", line 331, in wrapper
    return func(*args, **kwargs)
           ^^^^^^^^^^^^^^^^^^^^^
  File "/Users/nirmalgeorge/anaconda3/lib/python3.11/site-packages/pandas/core/generic.py", line 4492, in drop
    axis_name = self._get_axis_name(axis)
                ^^^^^^^^^^^^^^^^^^^^^^^^^
  File "/Users/nirmalgeorge/anaconda3/lib/python3.11/site-packages/pandas/core/generic.py", line 561, in _get_axis_name
    axis_number = cls._get_axis_number(axis)
                  ^^^^^^^^^^^^^^^^^^^^^^^^^^
  File "/Users/nirmalgeorge/anaconda3/lib/python3.11/site-packages/pandas/core/generic.py", line 556, in _get_axis_number
    raise ValueError(f"No axis named {axis} for object type {cls.__name__}")

The above exception occurred during handling of the following exception:
KeyError: 1

Stack Trace:
  File "/Users/nirmalgeorge/anaconda3/lib/python3.11/site-packages/pandas/core/generic.py", line 554, in _get_axis_number
    return cls._AXIS_TO_AXIS_NUMBER[axis]
           ~~~~~~~~~~~~~~~~~~~~~~~~^^^^^^
[0m
